Workbook

Sheet    PEDIDOS DA FABRICA
A1: Quantidade | B1: Nome do Produto | C1: Marca Produto | D1: LOJA | E1: LOJA 2 | F1: LOJA 3 | G1: PEDIDO LOJA | H1: PEDIDO LOJA 2 | I1: PEDIDO LOJA 3
A2: 0 | D2: 0 | E2: 0 | F2: 0 | G2: {=A2*D2} -> 0 | H2: {=A2*E2} -> 0 | I2: {=A2*F2} -> 0
A3: 0 | D3: 0 | E3: 0 | F3: 0 | G3: {=A3*D3} -> 0 | H3: {=A3*E3} -> 0 | I3: {=A3*F3} -> 0
A4: 0 | D4: 0 | E4: 0 | F4: 0 | G4: {=A4*D4} -> 0 | H4: {=A4*E4} -> 0 | I4: {=A4*F4} -> 0
A5: 0 | D5: 0 | E5: 0 | F5: 0 | G5: {=A5*D5} -> 0 | H5: {=A5*E5} -> 0 | I5: {=A5*F5} -> 0
A6: 0 | D6: 0 | E6: 0 | F6: 0 | G6: {=A6*D6} -> 0 | H6: {=A6*E6} -> 0 | I6: {=A6*F6} -> 0
A7: 0 | D7: 0 | E7: 0 | F7: 0 | G7: {=A7*D7} -> 0 | H7: {=A7*E7} -> 0 | I7: {=A7*F7} -> 0
A8: 0 | D8: 0 | E8: 0 | F8: 0 | G8: {=A8*D8} -> 0 | H8: {=A8*E8} -> 0 | I8: {=A8*F8} -> 0
A9: 0 | D9: 0 | E9: 0 | F9: 0 | G9: {=A9*D9} -> 0 | H9: {=A9*E9} -> 0 | I9: {=A9*F9} -> 0
A10: 0 | D10: 0 | E10: 0 | F10: 0 | G10: {=A10*D10} -> 0 | H10: {=A10*E10} -> 0 | I10: {=A10*F10} -> 0
A12: 0 | D12: 0 | E12: 0 | F12: 0 | G12: {=A12*D12} -> 0 | H12: {=A12*E12} -> 0 | I12: {=A12*F12} -> 0
A13: 0 | D13: 0 | E13: 0 | F13: 0 | G13: {=A13*D13} -> 0 | H13: {=A13*E13} -> 0 | I13: {=A13*F13} -> 0
A14: 0 | D14: 0 | E14: 0 | F14: 0 | G14: {=A14*D14} -> 0 | H14: {=A14*E14} -> 0 | I14: {=A14*F14} -> 0
... A38: 0 | D38: 0 | E38: 0 | F38: 0 | G38: {=A38*D38} -> 0 | H38: {=A38*E38} -> 0 | I38: {=A38*F38} -> 0
A39: Total | G39: TOTAL | H39: TOTAL | I39: TOTAL
A40: {=SUM(A2:A38)} -> 0 | G40: {=SUM(G2:G38)} -> 0 | H40: {=SUM(H2:H38)} -> 0 | I40: {=SUM(I2:I38)} -> 0
A49: Quantidade | B49: Nome do Produto | C49: Marca Produto | D49: Valor | E49: Total
A50: 0 | D50: 26 | E50: {=A50*D50} -> 0
A51: 0 | D51: 28 | E51: {=A51*D51} -> 0
A52: 0 | D52: 10 | E52: {=A52*D52} -> 0
A53: 0 | D53: 15 | E53: {=A53*D53} -> 0
A54: 0 | D54: 10 | E54: {=A54*D54} -> 0
A55: 0 | D55: 8 | E55: {=A55*D55} -> 0
A56: 0 | D56: 9 | E56: {=A56*D56} -> 0
A57: 0 | D57: 12 | E57: {=A57*D57} -> 0
A58: 0 | D58: 26 | E58: {=A58*D58} -> 0
A59: 0 | D59: 33 | E59: {=A59*D59} -> 0
A60: Total | B60: Frete | C60: Reais | E60: Total
A61: {=SUM(A50:A59)} -> 0 | B61: {=E61*20%+E61} -> 0 | C61: {=B61*5} -> 0 | E61: {=SUM(E50:E59)} -> 0

Sheet    ESTOQUE  2026
A1: Produto e Peso | B1: Marca | C1: Valor de Custo | D1: Valor de Venda | E1: Estoque | F1: Vendida | G1: Estoque Custo | H1: Estoque Venda | I1: Margem | J1: Lucro Unitário | K1: Previsão de Lucro Final | L1: Lucro Obtido | M1: Total Custo
A2: TIRZEPATIDA | B2: TG | C2: 620 | D2: 900 | E2: 14 | F2: 12 | G2: {=E2*C2} -> 8680 | H2: {=E2*D2} -> 12600 | I2: {=J2/D2} -> 0.31111111 | J2: {=D2-C2} -> 280 | K2: {=H2-G2} -> 3920 | L2: {=F2*J2} -> 3360 | M2: {=C2*F2} -> 7440
A3: TIRZEPATIDA | B3: LIPOLESS | C3: 620 | D3: 900 | E3: 17 | F3: 8 | G3: {=E3*C3} -> 10540 | H3: {=E3*D3} -> 15300 | I3: {=J3/D3} -> 0.31111111 | J3: {=D3-C3} -> 280 | K3: {=H3-G3} -> 4760 | L3: {=F3*J3} -> 2240 | M3: {=C3*F3} -> 4960
A4: TIRZEPATIDA | B4: TIRZEC | C4: 620 | D4: 900 | E4: 8 | F4: 4 | G4: {=E4*C4} -> 4960 | H4: {=E4*D4} -> 7200 | I4: {=J4/D4} -> 0.31111111 | J4: {=D4-C4} -> 280 | K4: {=H4-G4} -> 2240 | L4: {=F4*J4} -> 1120 | M4: {=C4*F4} -> 2480
A5: GHKCU | B5: EDGE VITAL | C5: 550 | D5: 1100 | E5: 0 | F5: 1 | G5: {=E5*C5} -> 0 | H5: {=E5*D5} -> 0 | I5: {=J5/D5} -> 0.5 | J5: {=D5-C5} -> 550 | K5: {=H5-G5} -> 0 | L5: {=F5*J5} -> 550 | M5: {=C5*F5} -> 550
A6: GHKCU | B6: SINEDICA | C6: 550 | D6: 1000 | E6: 0 | F6: 1 | G6: {=E6*C6} -> 0 | H6: {=E6*D6} -> 0 | I6: {=J6/D6} -> 0.45 | J6: {=D6-C6} -> 450 | K6: {=H6-G6} -> 0 | L6: {=F6*J6} -> 450 | M6: {=C6*F6} -> 550
A7: TIRZEPATIDA AMPOLA | B7: TG | C7: 155 | D7: 450 | E7: 4 | F7: 13 | G7: {=E7*C7} -> 620 | H7: {=E7*D7} -> 1800 | I7: {=J7/D7} -> 0.65555556 | J7: {=D7-C7} -> 295 | K7: {=H7-G7} -> 1180 | L7: {=F7*J7} -> 3835 | M7: {=C7*F7} -> 2015
A8: RETATRUTIDA | B8: SINEDICA | C8: 580 | D8: 1400 | E8: 0 | F8: 2 | G8: {=E8*C8} -> 0 | H8: {=E8*D8} -> 0 | I8: {=J8/D8} -> 0.58571429 | J8: {=D8-C8} -> 820 | K8: {=H8-G8} -> 0 | L8: {=F8*J8} -> 1640 | M8: {=C8*F8} -> 1160
A9: BOTOX | B9: DYSPORT | C9: 630 | D9: 1100 | E9: 45 | F9: 21 | G9: {=E9*C9} -> 28350 | H9: {=E9*D9} -> 49500 | I9: {=J9/D9} -> 0.42727273 | J9: {=D9-C9} -> 470 | K9: {=H9-G9} -> 21150 | L9: {=F9*J9} -> 9870 | M9: {=C9*F9} -> 13230
A10: PISA | B10: PERFUME | C10: 194 | D10: 300 | E10: 0 | F10: 1 | G10: {=E10*C10} -> 0 | H10: {=E10*D10} -> 0 | I10: {=J10/D10} -> 0.35333333 | J10: {=D10-C10} -> 106 | K10: {=H10-G10} -> 0 | L10: {=F10*J10} -> 106 | M10: {=C10*F10} -> 194
A11: CANETA GLOW | B11: ALLUVI | C11: 1000 | D11: 1700 | E11: 0 | F11: 0 | G11: {=E11*C11} -> 0 | H11: {=E11*D11} -> 0 | I11: {=J11/D11} -> 0.41176471 | J11: {=D11-C11} -> 700 | K11: {=H11-G11} -> 0 | L11: {=F11*J11} -> 0 | M11: {=C11*F11} -> 0
A12: MADAGASCAR | B12: CENTELLA | C12: 155 | D12: 200 | E12: 1 | F12: 0 | G12: =E12*C12 -> 155 | H12: {=E12*D12} -> 200 | I12: {=J12/D12} -> 0.225 | J12: {=D12-C12} -> 45 | K12: {=H12-G12} -> 45 | L12: {=F12*J12} -> 0 | M12: {=C12*F12} -> 0
A13: NUMBUZIN | B13: RETINAL | C13: 153 | D13: 200 | E13: 1 | F13: 0 | G13: {=E13*C13} -> 153 | H13: {=E13*D13} -> 200 | I13: {=J13/D13} -> 0.235 | J13: {=D13-C13} -> 47 | K13: {=H13-G13} -> 47 | L13: {=F13*J13} -> 0 | M13: {=C13*F13} -> 0
A14: MELATONIN | B14: NATROL | C14: 110 | D14: 180 | E14: 0 | F14: 1 | G14: {=E14*C14} -> 0 | H14: {=E14*D14} -> 0 | I14: {=J14/D14} -> 0.38888889 | J14: {=D14-C14} -> 70 | K14: {=H14-G14} -> 0 | L14: {=F14*J14} -> 70 | M14: {=C14*F14} -> 110
A15: CHANTS | B15: PERFUME | C15: 92 | D15: 350 | E15: 0 | F15: 1 | G15: {=E15*C15} -> 0 | H15: {=E15*D15} -> 0 | I15: {=J15/D15} -> 0.73714286 | J15: {=D15-C15} -> 258 | K15: {=H15-G15} -> 0 | L15: {=F15*J15} -> 258 | M15: {=C15*F15} -> 92
A16: SABAH SUGAR | B16: PERFUME | C16: 92 | D16: 350 | E16: 1 | F16: 0 | G16: {=E16*C16} -> 92 | H16: {=E16*D16} -> 350 | I16: {=J16/D16} -> 0.73714286 | J16: {=D16-C16} -> 258 | K16: {=H16-G16} -> 258 | L16: {=F16*J16} -> 0 | M16: {=C16*F16} -> 0
A17: SABAH AL WARD | B17: PERFUME | C17: 92 | D17: 350 | E17: 0 | F17: 0 | G17: {=E17*C17} -> 0 | H17: {=E17*D17} -> 0 | I17: {=J17/D17} -> 0.73714286 | J17: {=D17-C17} -> 258 | K17: {=H17-G17} -> 0 | L17: {=F17*J17} -> 0 | M17: {=C17*F17} -> 0
A18: KIT YARA | B18: PERFUME | C18: 169 | D18: 350 | E18: 1 | F18: 0 | G18: {=E18*C18} -> 169 | H18: {=E18*D18} -> 350 | I18: {=J18/D18} -> 0.51714286 | J18: {=D18-C18} -> 181 | K18: {=H18-G18} -> 181 | L18: {=F18*J18} -> 0 | M18: {=C18*F18} -> 0
A19: YARA ELIXIR | B19: PERFUME | C19: 186 | D19: 350 | E19: 1 | F19: 0 | G19: {=E19*C19} -> 186 | H19: {=E19*D19} -> 350 | I19: {=J19/D19} -> 0.46857143 | J19: {=D19-C19} -> 164 | K19: {=H19-G19} -> 164 | L19: {=F19*J19} -> 0 | M19: {=C19*F19} -> 0
A20: CARTELA | B20: CBC | C20: 300 | D20: 450 | E20: 0 | F20: 1 | G20: {=E20*C20} -> 0 | H20: {=E20*D20} -> 0 | I20: {=J20/D20} -> 0.33333333 | J20: {=D20-C20} -> 150 | K20: {=H20-G20} -> 0 | L20: {=F20*J20} -> 150 | M20: {=C20*F20} -> 300
G21: {=E21*C21} -> 0 | H21: {=E21*D21} -> 0 | I21: {=J21/D21} -> #DIV/0! | J21: {=D21-C21} -> 0 | K21: {=H21-G21} -> 0 | L21: {=F21*J21} -> 0 | M21: {=C21*F21} -> 0
G22: {=E22*C22} -> 0 | H22: {=E22*D22} -> 0 | I22: {=J22/D22} -> #DIV/0! | J22: {=D22-C22} -> 0 | K22: {=H22-G22} -> 0 | L22: {=F22*J22} -> 0 | M22: {=C22*F22} -> 0
G23: {=E23*C23} -> 0 | H23: {=E23*D23} -> 0 | I23: {=J23/D23} -> #DIV/0! | J23: {=D23-C23} -> 0 | K23: {=H23-G23} -> 0 | L23: {=F23*J23} -> 0 | M23: {=C23*F23} -> 0
G24: {=E24*C24} -> 0 | H24: {=E24*D24} -> 0 | I24: {=J24/D24} -> #DIV/0! | J24: {=D24-C24} -> 0 | K24: {=H24-G24} -> 0 | L24: {=F24*J24} -> 0 | M24: {=C24*F24} -> 0
G25: {=E25*C25} -> 0 | H25: {=E25*D25} -> 0 | I25: {=J25/D25} -> #DIV/0! | J25: {=D25-C25} -> 0 | K25: {=H25-G25} -> 0 | L25: {=F25*J25} -> 0 | M25: {=C25*F25} -> 0
G26: {=E26*C26} -> 0 | H26: {=E26*D26} -> 0 | I26: {=J26/D26} -> #DIV/0! | J26: {=D26-C26} -> 0 | K26: {=H26-G26} -> 0 | L26: {=F26*J26} -> 0 | M26: {=C26*F26} -> 0
G27: {=E27*C27} -> 0 | H27: {=E27*D27} -> 0 | I27: {=J27/D27} -> #DIV/0! | J27: {=D27-C27} -> 0 | K27: {=H27-G27} -> 0 | L27: {=F27*J27} -> 0 | M27: {=C27*F27} -> 0
G28: {=E28*C28} -> 0 | H28: {=E28*D28} -> 0 | I28: {=J28/D28} -> #DIV/0! | J28: {=D28-C28} -> 0 | K28: {=H28-G28} -> 0 | L28: {=F28*J28} -> 0 | M28: {=C28*F28} -> 0
G29: {=E29*C29} -> 0 | H29: {=E29*D29} -> 0 | I29: {=J29/D29} -> #DIV/0! | J29: {=D29-C29} -> 0 | K29: {=H29-G29} -> 0 | L29: {=F29*J29} -> 0 | M29: {=C29*F29} -> 0
G30: {=E30*C30} -> 0 | H30: {=E30*D30} -> 0 | I30: {=J30/D30} -> #DIV/0! | J30: {=D30-C30} -> 0 | K30: {=H30-G30} -> 0 | L30: {=F30*J30} -> 0 | M30: {=C30*F30} -> 0
G31: {=E31*C31} -> 0 | H31: {=E31*D31} -> 0 | I31: {=J31/D31} -> #DIV/0! | J31: {=D31-C31} -> 0 | K31: {=H31-G31} -> 0 | L31: {=F31*J31} -> 0 | M31: {=C31*F31} -> 0
G32: {=E32*C32} -> 0 | H32: {=E32*D32} -> 0 | I32: {=J32/D32} -> #DIV/0! | J32: {=D32-C32} -> 0 | K32: {=H32-G32} -> 0 | L32: {=F32*J32} -> 0 | M32: {=C32*F32} -> 0
G33: {=E33*C33} -> 0 | H33: {=E33*D33} -> 0 | I33: {=J33/D33} -> #DIV/0! | J33: {=D33-C33} -> 0 | K33: {=H33-G33} -> 0 | L33: {=F33*J33} -> 0 | M33: {=C33*F33} -> 0
E34: Quantidade Estoque: | F34: Quantidade Vendida: | G34: Estoque Atacado Total: | H34: Estoque Varejo Total: | I34: PORCENTAGEM META | K34: Previsão Total de Lucro: | L34: Lucro Obtido: | M34: Atacado saida:
E35: {=SUM(E2:E33)} -> 93 | F35: =SUM(F2:F33) -> 66 | G35: {=SUM(G2:G33)} -> 53905 | H35: {=SUM(H2:H33)} -> 87850 | I35: 0.5 | K35: {=H35-G35} -> 33945 | L35: {=SUM(L2:L33)} -> 23649 | M35: {=SUM(M2:M33)} -> 33081

Sheet CONTROLE DE SAÍDA 2026
A1: NOME | B1: MARCA | C1: QUANTIDADE | D1: VALOR DE CUSTO | E1: VALOR DE TOTAL DE VENDA | F1: CLIENTE
A2: RETRATUTIDA | B2: SINEDICA | C2: 1 | D2: 1000 | E2: 1700 | F2: EUDIS
A3: TIRZEPATIDA | B3: TG | C3: 1 | D3: 620 | E3: 840 | F3: TITU
A4: PISA | B4: PERFUME | C4: 1 | D4: 194 | E4: 300 | F4: EUDIS
A5: TIRZEPATIDA AMPOLA | B5: TG | C5: 1 | D5: 155 | E5: 300
A6: TIRZEPATIDA AMPOLA | B6: TG | C6: 2 | D6: 310 | E6: 600
A7: TIRZEPATIDA | B7: TG | C7: 1 | D7: 620 | E7: 840
A8: TIRZEPATIDA | B8: LIPOLESS | C8: 1 | D8: 620 | E8: 840
A9: TIRZEPATIDA | B9: TG | C9: 1 | D9: 620 | E9: 840
A10: TIRZEPATIDA | B10: LIPOLESS | C10: 1 | D10: 620 | E10: 840
A11: TIRZEPATIDA AMPOLA | B11: TG | C11: 1 | D11: 155 | E11: 400
A12: CHANTS | B12: PERFUME | C12: 1 | D12: 92 | E12: 350 | F12: ESPOSA FELIPE
A13: TIRZEPATIDA AMPOLA | B13: TG | C13: 1 | D13: 155 | E13: 400 | F13: DOUGLAS MERCEARIA
A14: TIRZEPATIDA AMPOLA | B14: TG | C14: 1 | D14: 155 | E14: 350 | F14: JUSSARA
A15: TIRZEPATIDA AMPOLA | B15: TG | C15: 1 | D15: 155 | E15: 350 | F15: JUSSARA
A16: GHKCU | B16: EDGE VITAL | C16: 1 | D16: 550 | E16: 1500 | F16: TITU L
A17: MELATONIN | B17: NATROL | C17: 1 | D17: 110 | E17: 180 | F17: ADRIANA
A18: TIRZEPATIDA | B18: LIPOLESS | C18: 1 | D18: 620 | E18: 940 | F18: TITU
A19: TIRZEPATIDA | B19: TG | C19: 1 | D19: 620 | E19: 940 | F19: TITU
A20: TIRZEPATIDA | B20: TIRZEC | C20: 1 | D20: 620 | E20: 1450 | F20: RAFAEL CIRCO
A21: TIRZEPATIDA | B21: TIRZEC | C21: 1 | D21: 620 | E21: 1450 | F21: RAFAEL CIRCO
A22: BOTOX | B22: DYSPORT | C22: 1 | D22: 580 | E22: 1100 | F22: MIKAEL BH
A23: BOTOX | B23: DYSPORT | C23: 1 | D23: 580 | E23: 780 | F23: NERY
... A39: TIRZEPATIDA | B39: LIPOLESS | C39: 2 | D39: 1240 | E39: 1680 | F39: TITU
F40: =SUM(D2:D43) -> 29031
F41: =SUM(E2:E43) -> 48750
F42: LUCRO MÊS AGOSTO | G42: {=F41-F40} -> 19719
F43: FIM DE AGOSTO/26 |ITENS VENDIDOS: | G43: =SUM(C2:C43) -> 58
A45: TIRZEPATIDA | B45: TG | C45: 1 | D45: 620 | E45: 988 | F45: FORD RANGER JUNIOR
A46: TIRZEPATIDA | B46: LIPOLESS | C46: 2 | D46: 1240 | E46: 1680 | F46: TITU
A47: RETRATUTIDA | B47: SYNEDICA | C47: 1 | D47: 580 | E47: 1200 | F47: JUNINHO PETROLUB
A48: RETRATUTIDA | B48: SYNEDICA | C48: 1 | D48: 580 | E48: 1400 | F48: IGOR LAVA JATO
A49: TIRZEPATIDA | B49: LIPOLESS | C49: 1 | D49: 620 | E49: 800 | F49: ZE CARLINHO
A50: GHKCU | B50: SYNEDICA | C50: 1 | D50: 580 | E50: 800 | F50: ZE CARLINNO
A51: TIRZEPATIDA AMPOLA | B51: TG | C51: 1 | D51: 155 | E51: 400 | F51: MARCIA GOMES JU
A52: TIRZEPATIDA AMPOLA | B52: TG | C52: 1 | D52: 155 | E52: 300 | F52: LORENA MERCEARIA
A53: TIRZEPATIDA AMPOLA | B53: TG | C53: 1 | D53: 155 | E53: 400 | F53: AMIGA KETY
A54: TIRZEPATIDA | B54: TG | C54: 1 | D54: 620 | E54: 900 | F54: KLEBER
A55: BOTOX | B55: DYSPORT | C55: 1 | D55: 630 | E55: 1000 | F55: CAROL MARTINS
F89: {=SUM(D45:D92)} -> 5935
...

Sheet CONTA 2026
A1: SAÍDA | B1: DATA | C1: VALOR | E1: TOTAL SAÍDA | F1: TOTAL ENTRADAS | H1: AGUARDANDO | I1: PAGAMENTO | J1: DATA | L1: MÊS | M1: QUANTIDADE | N1: BRUTO | O1: LUCRO | P1: CUSTO FIXO/VARIADO | Q1: PRO-LABORE | R1: INVESTIR
A2: Comissão Alicy | B2: 46258 | C2: 400 | E2: =' ESTOQUE 2026'!M35 -> 33081 | F2: ='CONTROLE DE SAÍDA 2026'!E601 -> 58618 | H2: TITU L | I2: 1425 | J2: 46275 | L2: AGOSTO/26 | M2: {='CONTROLE DE SAÍDA 2026'!G43} -> 58 | N2: {='CONTROLE DE SAÍDA 2026'!F41} -> 48750 | O2: {='CONTROLE DE SAÍDA 2026'!G42} -> 19719 | P2: =O2/3 -> 6573 | Q2: =P2 -> 6573 | R2: =Q2 -> 6573
A3: SAQUE MES 8 | B3: 46265 | C3: 19719 | E3: =C59 -> 20119 | F3: =F2-(E2+E3) -> 5418 | H3: TITU | I3: 750 | L3: SETEMBRO/26 | M3: {='CONTROLE DE SAÍDA 2026'!G92} -> 12 | N3: {='CONTROLE DE SAÍDA 2026'!F90} -> 9868 | O3: {='CONTROLE DE SAÍDA 2026'!G91} -> 3933 | P3: =O3/3 -> 1311 | Q3: =P3 -> 1311 | R3: =Q3 -> 1311
E4: FIADO + SALDO | H4: ADRIANA | I4: 90 | J4: 46283 | L4: MARÇO | M4: {='CONTROLE DE SAÍDA 2026'!G163} -> 0 | N4: {='CONTROLE DE SAÍDA 2026'!F161} -> 0 | O4: {='CONTROLE DE SAÍDA 2026'!G162} -> 0 | P4: =O4/3 -> 0 | Q4: =P4 -> 0 | R4: =Q4 -> 0
H5: RAFAEL CIRCO | I5: 1350 | J5: 46275 | L5: ABRIL | M5: {='CONTROLE DE SAÍDA 2026'!G236} -> 0 | N5: {='CONTROLE DE SAÍDA 2026'!F234} -> 0 | O5: {='CONTROLE DE SAÍDA 2026'!G235} -> 0 | P5: =O5/3 -> 0 | Q5: =P5 -> 0 | R5: =Q5 -> 0
H6: RODRIGO ELETRI | I6: 1000 | L6: JUNHO | M6: {='CONTROLE DE SAÍDA 2026'!G337} -> 0 | N6: {='CONTROLE DE SAÍDA 2026'!F335} -> 0 | O6: {='CONTROLE DE SAÍDA 2026'!G336} -> 0 | P6: =O6/3 -> 0 | Q6: =P6 -> 0 | R6: =Q6 -> 0
H7: PATRÍCIA NERY | I7: 9000 | J7: 46305 | L7: JULHO | M7: {='CONTROLE DE SAÍDA 2026'!G398} -> 0 | N7: {='CONTROLE DE SAÍDA 2026'!F396} -> 0 | O7: {='CONTROLE DE SAÍDA 2026'!G397} -> 0 | P7: =O7/3 -> 0 | Q7: =P7 -> 0 | R7: =Q7 -> 0
H8: MIKAELA BH | I8: 4400 | J8: 46281 | L8: AGOSTO | M8: ='CONTROLE DE SAÍDA 2026'!G435 -> 0 | N8: ='CONTROLE DE SAÍDA 2026'!F433 -> 0 | O8: ='CONTROLE DE SAÍDA 2026'!G434 -> 0 | P8: =O8/3 -> 0 | Q8: =P8 -> 0 | R8: =Q8 -> 0
H9: MIKAELA BH | I9: 4400 | J9: 46311
H10: FILIPE GELADEIRA | I10: 3826
H11: ALICE LOJA | I11: 162.5
H12: ZÉ CARLINHO | I12: 100
H13: PETROLUB | I13: 600 | L13: SETEMBRO | M13: ='CONTROLE DE SAÍDA 2026'!G479 -> 0 | N13: ='CONTROLE DE SAÍDA 2026'!F477 -> 0 | O13: ='CONTROLE DE SAÍDA 2026'!G478 -> 0 | P13: =O13/3 -> 0 | Q13: =P13 -> 0 | R13: =Q13 -> 0
H14: IGOR LAVA LAJO | I14: 1400 | L14: OUTUBRO | M14: ='CONTROLE DE SAÍDA 2026'!G515 -> 0 | N14: ='CONTROLE DE SAÍDA 2026'!F513 -> 0 | O14: ='CONTROLE DE SAÍDA 2026'!G514 -> 0 | P14: =O14/3 -> 0 | Q14: =P14 -> 0 | R14: =Q14 -> 0
H15: TOTAL | I15: {=SUM(I2:I14)} -> 28503.5 | L15: NOVEMBRO | M15: ='CONTROLE DE SAÍDA 2026'!G533 -> 0 | N15: ='CONTROLE DE SAÍDA 2026'!F531 -> 0 | O15: ='CONTROLE DE SAÍDA 2026'!G532 -> 0 | P15: =O15/3 -> 0 | Q15: =P15 -> 0 | R15: =Q15 -> 0
L16: DEZEMBRO | M16: ='CONTROLE DE SAÍDA 2026'!G581 -> 0 | N16: ='CONTROLE DE SAÍDA 2026'!F579 -> 0 | O16: ='CONTROLE DE SAÍDA 2026'!G580 -> 0 | P16: =O16/3 -> 0 | Q16: =P16 -> 0 | R16: =Q16 -> 0
E17: DIVIDA RESTANTE | F17: {=SUM(F6:F16)} -> 0 | L17: TOTAL | M17: {=SUM(M2:M16)} -> 70 | O17: {=SUM(O2:O16)} -> 23652 | P17: {=SUM(P2:P16)} -> 7884 | Q17: {=SUM(Q2:Q16)} -> 7884 | R17: {=SUM(R2:R16)} -> 7884
B59: TOTAL | C59: {=SUM(C2:C58)} -> 20119
